<mujoco model="ur3_onrobot_rg2">
  <compiler angle="radian" meshdir="meshes/"/>

  <asset>
    <mesh name="base_001" content_type="model/stl" file="base_001.stl"/>
    <mesh name="shoulder_001" content_type="model/stl" file="shoulder_001.stl"/>
    <mesh name="upperarm_001" content_type="model/stl" file="upperarm_001.stl"/>
    <mesh name="forearm_001" content_type="model/stl" file="forearm_001.stl"/>
    <mesh name="wrist1_001" content_type="model/stl" file="wrist1_001.stl"/>
    <mesh name="wrist2_001" content_type="model/stl" file="wrist2_001.stl"/>
    <mesh name="wrist3_001" content_type="model/stl" file="wrist3_001.stl"/>
    <mesh name="base_link_001" content_type="model/stl" file="base_link_001.stl"/>
    <mesh name="outer_knuckle_001" content_type="model/stl" file="outer_knuckle_001.stl"/>
    <mesh name="inner_knuckle_001" content_type="model/stl" file="inner_knuckle_001.stl"/>
    <mesh name="inner_finger_001" content_type="model/stl" file="inner_finger_001.stl"/>
  </asset>

  <worldbody>
    <geom quat="-1 0 0 0" type="mesh" rgba="0.7 0.7 0.7 1" mesh="base_001"/>
    <body name="shoulder_link" pos="0 0 0.1519" quat="0 0 0 1">
      <inertial pos="0 0 -0.02" mass="2" diaginertia="0.00809317 0.00809317 0.005625"/>
      <joint name="shoulder_pan_joint" pos="0 0 0" axis="0 0 1" range="-6.28319 6.28319" actuatorfrcrange="-56 56"/>
      <geom quat="0 0 0 1" type="mesh" rgba="0.7 0.7 0.7 1" mesh="shoulder_001"/>
      <body name="upper_arm_link" quat="0.707107 0.707107 0 0">
        <inertial pos="-0.11365 0 0.1157" mass="3.42" diaginertia="0.0217285 0.0217285 0.00961875"/>
        <joint name="shoulder_lift_joint" pos="0 0 0" axis="0 0 1" range="-6.28319 6.28319" actuatorfrcrange="-56 56"/>
        <geom pos="0 0 0.1198" quat="0.5 0.5 -0.5 -0.5" type="mesh" rgba="0.7 0.7 0.7 1" mesh="upperarm_001"/>
        <body name="forearm_link" pos="-0.24365 0 0">
          <inertial pos="-0.16325 0 0.0238" mass="1.26" diaginertia="0.00654681 0.00654681 0.00354375"/>
          <joint name="elbow_joint" pos="0 0 0" axis="0 0 1" range="-3.14159 3.14159" actuatorfrcrange="-28 28"/>
          <geom pos="0 0 0.0275" quat="0.5 0.5 -0.5 -0.5" type="mesh" rgba="0.7 0.7 0.7 1" mesh="forearm_001"/>
          <body name="wrist_1_link" pos="-0.21325 0 0.11235">
            <inertial pos="0 -0.01 0" quat="0.5 0.5 -0.5 0.5" mass="0.8" diaginertia="0.00225 0.00161064 0.00161064"/>
            <joint name="wrist_1_joint" pos="0 0 0" axis="0 0 1" range="-6.28319 6.28319" actuatorfrcrange="-12 12"/>
            <geom pos="0 0 -0.085" quat="0.707107 0.707107 0 0" type="mesh" rgba="0.7 0.7 0.7 1" mesh="wrist1_001"/>
            <body name="wrist_2_link" pos="0 -0.08535 -1.75056e-11" quat="0.707107 0.707107 0 0">
              <inertial pos="0 0.01 0" quat="0.5 0.5 -0.5 0.5" mass="0.8" diaginertia="0.00225 0.00157217 0.00157217"/>
              <joint name="wrist_2_joint" pos="0 0 0" axis="0 0 1" range="-6.28319 6.28319" actuatorfrcrange="-12 12"/>
              <geom pos="0 0 -0.083" quat="1 0 0 0" type="mesh" rgba="0.7 0.7 0.7 1" mesh="wrist2_001"/>
              <body name="wrist_3_link" pos="0 0.0819 -1.6798e-11" quat="0.707107 -0.707107 0 0">
                <inertial pos="0 0 -0.00666667" quat="0.923792 0.00525909 -0.0126966 0.382647" mass="1.05" diaginertia="0.00123064 0.0012286 0.00117916"/>
                <joint name="wrist_3_joint" pos="0 0 0" axis="0 0 1" range="-6.28319 6.28319" actuatorfrcrange="-12 12"/>
                <geom pos="0 -0.00255 -0.082" quat="0.707107 0.707107 0 0" type="mesh" rgba="0.7 0.7 0.7 1" mesh="wrist3_001"/>
                <geom type="mesh" rgba="0.8 0.8 0.8 1" mesh="base_link_001"/>
                <body name="left_outer_knuckle" pos="0 -0.017178 0.125797" quat="1 0 0 0">
                  <inertial pos="0 0 0" quat="0.820473 0.339851 -0.17592 0.424708" mass="0.05" diaginertia="0.001002 0.000999 0.000999"/>
                  <joint name="finger_joint" pos="0 0 0" axis="-1 0 0" range="-0.558505 0.785398" actuatorfrcrange="-1000 1000"/>
                  <geom type="mesh" rgba="0.8 0.8 0.8 1" mesh="outer_knuckle_001"/>
                  <body name="left_inner_finger" pos="0 -0.039592 0.038177">
                    <inertial pos="0 0 0" quat="0.820473 0.339851 -0.17592 0.424708" mass="0.05" diaginertia="0.001002 0.000999 0.000999"/>
                    <joint name="left_inner_finger_joint" pos="0 0 0" axis="1 0 0" range="-0.872665 0.872665" actuatorfrcrange="-1000 1000"/>
                    <geom type="mesh" rgba="0.1 0.1 0.1 1" mesh="inner_finger_001"/>
                  </body>
                </body>
                <body name="left_inner_knuckle" pos="0 -0.007678 0.142297" quat="1 0 0 0">
                  <inertial pos="0 0 0" quat="0.820473 0.339851 -0.17592 0.424708" mass="0.05" diaginertia="0.001002 0.000999 0.000999"/>
                  <joint name="left_inner_knuckle_joint" pos="0 0 0" axis="1 0 0" range="-0.785398 0.785398" actuatorfrcrange="-1000 1000"/>
                  <geom type="mesh" rgba="0.8 0.8 0.8 1" mesh="inner_knuckle_001"/>
                </body>
                <body name="right_outer_knuckle" pos="0 0.017178 0.125797" quat="0 0 0 1">
                  <inertial pos="0 0 0" quat="0.820473 0.339851 -0.17592 0.424708" mass="0.05" diaginertia="0.001002 0.000999 0.000999"/>
                  <joint name="right_outer_knuckle_joint" pos="0 0 0" axis="1 0 0" range="-0.785398 0.785398" actuatorfrcrange="-1000 1000"/>
                  <geom type="mesh" rgba="0.8 0.8 0.8 1" mesh="outer_knuckle_001"/>
                  <body name="right_inner_finger" pos="0 -0.039592 0.038177">
                    <inertial pos="0 0 0" quat="0.820473 0.339851 -0.17592 0.424708" mass="0.05" diaginertia="0.001002 0.000999 0.000999"/>
                    <joint name="right_inner_finger_joint" pos="0 0 0" axis="1 0 0" range="-0.872665 0.872665" actuatorfrcrange="-1000 1000"/>
                    <geom type="mesh" rgba="0.1 0.1 0.1 1" mesh="inner_finger_001"/>
                  </body>
                </body>
                <body name="right_inner_knuckle" pos="0 0.007678 0.142297" quat="0 0 0 -1">
                  <inertial pos="0 0 0" quat="0.820473 0.339851 -0.17592 0.424708" mass="0.05" diaginertia="0.001002 0.000999 0.000999"/>
                  <joint name="right_inner_knuckle_joint" pos="0 0 0" axis="1 0 0" range="-0.785398 0.785398" actuatorfrcrange="-1000 1000"/>
                  <geom type="mesh" rgba="0.8 0.8 0.8 1" mesh="inner_knuckle_001"/>
                </body>
              </body>
            </body>
          </body>
        </body>
      </body>
    </body>
  </worldbody>
</mujoco>
